Workbook

Sheet Fluxo de Caixa
A1: Lançamento
A3: Data | B3: Descrição | C3: Categoria | D3: Valor (R$) | E3: Forma de Pagamento | F3: Quantidade
A4: 45801 | B4: 1 piscina | C4: Entrada | D4: 8 | E4: Pix | F4: 1
A7: 45801 | B7: 1 piscina | C7: Entrada | D7: 8 | E7: Pix | F7: 1
A8: 45801 | B8: 1 nutella | C8: Entrada | D8: 7.5 | E8: Pix | F8: 1
A9: 45801 | B9: 1 piscina e 1 combinado | C9: Entrada | D9: 20 | E9: Pix | F9: 3
A10: 45801 | B10: 1 piscina e 1 combinado | C10: Entrada | D10: 20 | E10: Pix | F10: 3
A11: 45801 | B11: 1 piscina e 1 combinado | C11: Entrada | D11: 20 | E11: Pix | F11: 3
A12: 45801 | B12: 1 classico | C12: Entrada | D12: 6.5 | E12: Pix | F12: 1
A13: 45801 | B13: 1 piscina e 1 combinado | C13: Entrada | D13: 20 | E13: Pix | F13: 3
A14: 45801 | B14: 1 classico | C14: Entrada | D14: 6.5 | E14: Pix | F14: 1
A15: 45801 | B15: 3 combinados | C15: Entrada | D15: 32 | E15: Pix | F15: 6
A16: 45801 | B16: 1 piscina | C16: Entrada | D16: 8 | E16: Pix | F16: 1
A17: 45801 | B17: 1 piscina | C17: Entrada | D17: 8 | E17: Pix | F17: 1
... A30: 45801 | B30: 1 piscina | C30: Entrada | D30: 8 | E30: Pix | F30: 1
A31: 45801 | B31: uber | C31: Entrada | D31: 1.25 | E31: Pix
A32: 45801 | B32: uber | C32: Saida | D32: 11.8 | E32: Pix
A33: 45801 | B33: 1 piscina e 1 classico | C33: Entrada | D33: 14.5 | E33: Pix | F33: 3
A34: 45801 | B34: 1 classico | C34: Entrada | D34: 6.5 | E34: Pix | F34: 1
A35: 45801 | B35: 1 piscina e 1 combinado | C35: Entrada | D35: 20 | E35: Pix | F35: 3
A36: 45801 | B36: 1 piscina | C36: Entrada | D36: 8 | E36: Pix | F36: 1
A37: 45801 | B37: 1 piscina | C37: Entrada | D37: 8 | E37: Pix | F37: 1
A38: 45801 | B38: completar | C38: Entrada | D38: 1.5 | E38: Pix
A39: 45801 | B39: 2 piscina | C39: Entrada | D39: 16 | E39: Pix | F39: 2
A40: 45801 | B40: 1 combinado e 1 piscina | C40: Entrada | D40: 20 | E40: Pix | F40: 3
A41: 45801 | B41: 2 combinados | C41: Entrada | D41: 24 | E41: Pix | F41: 4
A42: 45801 | B42: 1 piscina | C42: Entrada | D42: 8 | E42: Pix | F42: 1
A43: 45801 | B43: 1 piscina | C43: Entrada | D43: 8 | E43: Pix | F43: 1
A44: 45801 | B44: 1 piscina | C44: Entrada | D44: 8 | E44: Pix | F44: 1
A45: 45801 | B45: 1 piscina | C45: Entrada | D45: 8 | E45: Pix | F45: 1
A46: 45801 | B46: 5 piscinas | C46: Entrada | D46: 39 | E46: Pix | F46: 5
A47: 45801 | B47: insumo | C47: Saida | D47: 48.79 | E47: Pix
A48: 45801 | B48: 1 classico | C48: Entrada | D48: 6.5 | E48: Pix | F48: 1
A49: 45801 | B49: 10 classicos | C49: Entrada | D49: 60 | E49: Pix | F49: 10
A50: 45801 | B50: 1 piscina | C50: Entrada | D50: 8 | E50: Pix | F50: 1
A51: 45801 | B51: 1 bolinho de Nutella e 1 piscina | C51: Entrada | D51: 16 | E51: Pix | F51: 2
A52: 45801 | B52: 10 combinados | C52: Entrada | D52: 120 | E52: Pix | F52: 20
A53: 45801 | B53: 1 piscina e 1 classico | C53: Entrada | D53: 14.5 | E53: Pix | F53: 2
A54: 45800 | B54: 5 classico | C54: Entrada | D54: 30 | E54: Pix | F54: 5
A55: 45800 | B55: 1 piscina | C55: Entrada | D55: 8 | E55: Pix | F55: 1
...

Sheet Acompanhamento da Meta
E4: Acompanhamento da Meta
E6: Faturamento Total | F6: Despesas Totais | G6: Lucro Bruto
E7: =SUMIF('Fluxo de Caixa'!$C$5:$C$1467, "Entrada", 'Fluxo de Caixa'!$D$5:$D$1467) -> 7674.15 | F7: =SUMIF('Fluxo de Caixa'!$C$5:$C$1467, "Saida ", 'Fluxo de Caixa'!$D$5:$D$1467) -> 2598.45 | G7: =E7-F7 -> 5075.7

Sheet Planilha de Vendas
A1: Planilha Vendas
A2: Data | B2: Cliente | C2: Quantidade Casadinhas | D2: Quantidade Classicos | E2: Quantidade Avelã | F2: Quantidade Piscininhas | G2: Quantidade Total | H2: Produziu? | I2: Entregou?
A3: 45803 | B3: Luis Mario | F3: 1 | G3: =(C3*2)+D3+E3+F3 -> 1 | H3: TRUE | I3: TRUE
A4: 45803 | B4: Gabriel | C4: 1 | F4: 1 | G4: =(C4*2)+D4+E4+F4 -> 3 | H4: TRUE | I4: TRUE
A5: 45802 | B5: Rodrigo | D5: 1 | G5: =(C5*2)+D5+E5+F5 -> 1 | H5: TRUE | I5: TRUE
A6: 45802 | B6: Alexandre | C6: 1 | F6: 1 | G6: =(C6*2)+D6+E6+F6 -> 3 | H6: TRUE | I6: TRUE
A7: 45802 | B7: Gustavo | D7: 1 | G7: =(C7*2)+D7+E7+F7 -> 1 | H7: TRUE | I7: TRUE
A8: 45802 | B8: Joao | F8: 1 | G8: =(C8*2)+D8+E8+F8 -> 1 | H8: TRUE | I8: TRUE
A9: 45802 | B9: Victor | F9: 3 | G9: =(C9*2)+D9+E9+F9 -> 3 | H9: TRUE | I9: TRUE
A10: 45802 | B10: Pedro | F10: 1 | G10: =(C10*2)+D10+E10+F10 -> 1 | H10: TRUE | I10: TRUE
A11: 45802 | B11: Paulo | F11: 1 | G11: =(C11*2)+D11+E11+F11 -> 1 | H11: TRUE | I11: TRUE
A12: 45802 | B12: Maria | F12: 4 | G12: =(C12*2)+D12+E12+F12 -> 4 | H12: TRUE | I12: TRUE
A13: 45802 | B13: Paula | F13: 1 | G13: =(C13*2)+D13+E13+F13 -> 1 | H13: TRUE | I13: TRUE
A14: 45802 | B14: Manoela | F14: 1 | G14: =(C14*2)+D14+E14+F14 -> 1 | H14: TRUE | I14: TRUE
A15: 45802 | B15: Nara | F15: 1 | G15: =(C15*2)+D15+E15+F15 -> 1 | H15: TRUE | I15: TRUE
A16: 45802 | B16: Bruno | C16: 1 | G16: =(C16*2)+D16+E16+F16 -> 2 | H16: TRUE | I16: TRUE
A17: 45802 | B17: Ana | D17: 1 | G17: =(C17*2)+D17+E17+F17 -> 1 | H17: TRUE | I17: TRUE
A18: 45802 | B18: Valentina | F18: 1 | G18: =(C18*2)+D18+E18+F18 -> 1 | H18: TRUE | I18: TRUE
A19: 45802 | B19: Livia | F19: 1 | G19: =(C19*2)+D19+E19+F19 -> 1 | H19: TRUE | I19: TRUE
A20: 45802 | B20: Yasmin | F20: 1 | G20: =(C20*2)+D20+E20+F20 -> 1 | H20: TRUE | I20: TRUE
A21: 45802 | B21: Julia | E21: 1 | G21: =(C21*2)+D21+E21+F21 -> 1 | H21: TRUE | I21: TRUE
A22: 45801 | B22: Doação | D22: 50 | G22: 50 | H22: TRUE | I22: TRUE
A23: 45801 | B23: Nicole | F23: 1 | G23: =(C23*2)+D23+E23+F23 -> 1 | H23: TRUE | I23: TRUE
A24: 45801 | B24: Bruna | C24: 1 | F24: 1 | G24: =(C24*2)+D24+E24+F24 -> 3 | H24: TRUE | I24: TRUE
A25: 45801 | B25: Paula | F25: 1 | G25: =(C25*2)+D25+E25+F25 -> 1 | H25: TRUE | I25: TRUE
A26: 45801 | B26: Mariana | F26: 1 | G26: =(C26*2)+D26+E26+F26 -> 1 | H26: TRUE | I26: TRUE
A27: 45801 | B27: Maria | F27: 2 | G27: =(C27*2)+D27+E27+F27 -> 2 | H27: TRUE | I27: TRUE
A28: 45801 | B28: Yasmin | F28: 1 | G28: =(C28*2)+D28+E28+F28 -> 1 | H28: TRUE | I28: TRUE
A29: 45801 | B29: Livia | F29: 1 | G29: =(C29*2)+D29+E29+F29 -> 1 | H29: TRUE | I29: TRUE
A30: 45801 | B30: Isadora | F30: 1 | G30: =(C30*2)+D30+E30+F30 -> 1 | H30: TRUE | I30: TRUE
A31: 45801 | B31: Talita | C31: 1 | F31: 1 | G31: =(C31*2)+D31+E31+F31 -> 3 | H31: TRUE | I31: TRUE
A32: 45801 | B32: Myrna | C32: 2 | G32: =(C32*2)+D32+E32+F32 -> 4 | H32: TRUE | I32: TRUE
A33: 45801 | B33: Valentina | F33: 1 | G33: =(C33*2)+D33+E33+F33 -> 1 | H33: TRUE | I33: TRUE
A34: 45801 | B34: Renata | D34: 6 | G34: =(C34*2)+D34+E34+F34 -> 6 | H34: TRUE | I34: TRUE
A35: 45801 | B35: Julio | D35: 1 | G35: =(C35*2)+D35+E35+F35 -> 1 | H35: TRUE | I35: TRUE
A36: 45801 | B36: Gabriel | D36: 10 | G36: =(C36*2)+D36+E36+F36 -> 10 | H36: TRUE | I36: TRUE
A37: 45801 | B37: João Alecrim | F37: 1 | G37: =(C37*2)+D37+E37+F37 -> 1 | H37: TRUE | I37: TRUE
A38: 45801 | B38: João | F38: 2 | G38: =(C38*2)+D38+E38+F38 -> 2 | H38: TRUE | I38: TRUE
A39: 45800 | B39: Paulo | C39: 2 | D39: 1 | G39: =(C39*2)+D39+E39+F39 -> 5 | H39: TRUE | I39: TRUE
A40: 45800 | B40: Fernando | F40: 1 | G40: =(C40*2)+D40+E40+F40 -> 1 | H40: TRUE | I40: TRUE
...

Sheet Vendas 
D7: Acompanhamento da Meta
D9: Quantidade Casadinhas | E9: Quantidade Classicas | F9: Quantidade Avelã | G9: Quantidade Piscininhas | H9: Quantidade Total
D10: =SUM('Planilha de Vendas'!$C$5:$C$1328) -> 202 | E10: =SUM('Planilha de Vendas'!$D$5:$D$1328) -> 460 | F10: =SUM('Planilha de Vendas'!$E$5:$E$1328) -> 52 | G10: =SUM('Planilha de Vendas'!$F$5:$F$1328) -> 161 | H10: =(D10*2)+E10+F10+G10 -> 1077
D15: Segunda Feira
D17: Quantidade Casadinhas | E17: Quantidade Classicas | F17: Quantidade Avelã | G17: Quantidade Piscininhas | H17: Quantidade Total
D18: 26 | E18: 26 | F18: 8 | G18: 0 | H18: =D18*2+E18+F18+G18 -> 86
D23: Terça Feira
D25: Quantidade Casadinhas | E25: Quantidade Classicas | F25: Quantidade Avelã | G25: Quantidade Piscininhas | H25: Quantidade Total
D26: 17 | E26: 123 | F26: 4 | G26: 21 | H26: =D26*2+E26+F26+G26 -> 182
D30: Quarta Feira
D32: Quantidade Casadinhas | E32: Quantidade Classicas | F32: Quantidade Avelã | G32: Quantidade Piscininhas | H32: Quantidade Total
D33: 56 | E33: 72 | F33: 16 | G33: 42 | H33: =D33*2+E33+F33+G33 -> 242
D38: Quinta Feira
D40: Quantidade Casadinhas | E40: Quantidade Classicas | F40: Quantidade Avelã | G40: Quantidade Piscininhas | H40: Quantidade Total
D41: 54 | E41: 78 | F41: 15 | G41: 56 | H41: =D41*2+E41+F41+G41 -> 257
D45: Sexta Feira
D47: Quantidade Casadinhas | E47: Quantidade Classicas | F47: Quantidade Avelã | G47: Quantidade Piscininhas | H47: Quantidade Total
D48: 42 | E48: 91 | F48: 8 | G48: 11 | H48: =D48*2+E48+F48+G48 -> 194
D52: Sabado
D54: Quantidade Casadinhas | E54: Quantidade Classicas | F54: Quantidade Avelã | G54: Quantidade Piscininhas | H54: Quantidade Total
D55: 4 | E55: 67 | F55: 0 | G55: 14 | H55: =D55*2+E55+F55+G55 -> 89
D59: Domingo
D61: Quantidade Casadinhas | E61: Quantidade Classicas | F61: Quantidade Avelã | G61: Quantidade Piscininhas | H61: Quantidade Total
D62: 2 | E62: 3 | F62: 1 | G62: 19 | H62: =D62*2+E62+F62+G62 -> 27
D67: Segunda
D69: Quantidade Casadinhas | E69: Quantidade Classicas | F69: Quantidade Avelã | G69: Quantidade Piscininhas | H69: Quantidade Total
D70: 1 | E70: 0 | F70: 0 | G70: 1 | H70: =D70*2 +G70 -> 3

Sheet Estoque Atual 
B3: Estoque Atual | E3: Compras | J3: Gasto por Dia (12) | M3: Estoque Ideal | P3: Gasto por Fornada
B4: Itens | C4: Quantidade | E4: Itens | F4: Quantidade | G4: Preço Unitario | H4: Valor Final | J4: Itens | K4: Quantidade | M4: Itens | N4: Quantidade | P4: Itens | Q4: Quantidade
B5: Óleo(und) | C5: 0 | E5: Óleo(und) | H5: =F5*G5 -> 0 | J5: Óleo(und) | K5: =K22*12 -> 0 | M5: Óleo(und) | N5: 8 | P5: Óleo(und) | Q5: 0.33
B6: Açúcar(kg) | C6: 0 | E6: Açúcar(kg) | H6: =F6*G6 -> 0 | J6: Açúcar(kg) | K6: =K23*12 -> 0 | M6: Açúcar(kg) | N6: 12 | P6: Açúcar(kg) | Q6: 0.55
B7: Farinha(kg) | C7: 0 | E7: Farinha(kg) | H7: =F7*G7 -> 0 | J7: Farinha(kg) | K7: =K24*12 -> 0 | M7: Farinha(kg) | N7: 8 | P7: Farinha(kg) | Q7: 0.4
B8: Chocolate(g) | C8: 0 | E8: Chocolate(g) | H8: =F8*G8 -> 0 | J8: Chocolate(g) | K8: =K25*12 -> 0 | M8: Chocolate(g) | N8: 800 | P8: Chocolate(g) | Q8: 36
B9: Ovos(und) | C9: 0 | E9: Ovos(und) | H9: =F9*G9 -> 0 | J9: Ovos(und) | K9: =K26*12 -> 0 | M9: Ovos(und) | N9: 120 | P9: Ovos(und) | Q9: 6
B10: Creme de Leite(cx) | C10: 0 | E10: Creme de Leite(cx) | H10: =F10*G10 -> 0 | J10: Creme de Leite(cx) | K10: =K27*12 -> 0 | M10: Creme de Leite(cx) | N10: 15 | P10: Creme de Leite(cx) | Q10: 0.67
B11: Leite Condensado(cx) | C11: 0 | E11: Leite Condensado(cx) | H11: =F11*G11 -> 0 | J11: Leite Condensado(cx) | K11: =K28*12 -> 0 | M11: Leite Condensado(cx) | N11: 27 | P11: Leite Condensado(cx) | Q11: 1.17
B12: Margarina (kg) | C12: 0 | E12: Margarina (kg) | H12: =F12*G12 -> 0 | J12: Margarina (kg) | K12: =K29*12 -> 0 | M12: Margarina (kg) | N12: 1 | P12: Margarina (kg) | Q12: 0.02
B13: Cenoura (kg) | C13: 0 | E13: Cenoura (kg) | H13: =F13*G13 -> 0 | J13: Cenoura (kg) | K13: =K30*12 -> 0 | M13: Cenoura (kg) | N13: 9 | P13: Cenoura (kg) | Q13: 0.4
B14: Creme de Avelã(kg) | C14: 0 | E14: Creme de Avelã(kg) | H14: =F14*G14 -> 0 | J14: Creme de Avelã(kg) | K14: =K31*12 -> 0 | M14: Creme de Avelã(kg) | N14: 3 | P14: Creme de Avelã(kg) | Q14: 0.4
B15: Adesivos (und) | C15: 0 | E15: Adesivos (und) | H15: =F15*G15 -> 0 | J15: Adesivos (und) | K15: =K32*12 -> 0 | M15: Adesivos (und) | N15: 700 | P15: Adesivos (und) | Q15: 24
B16: Potinhos Plastico(und) | C16: 0 | E16: Potinhos Plastico(und) | H16: =F16*G16 -> 0 | J16: Potinhos Plastico(und) | K16: Depende da demanda | M16: Potinhos Plastico(und) | N16: depende da demanda | P16: Potinhos Plastico(und) | Q16: Depende da Demanda
B17: Papel embalagem(und) | C17: 0 | E17: Papel embalagem(und) | H17: =F17*G17 -> 0 | J17: Papel embalagem(und) | K17: =K34*12 -> 0 | M17: Papel embalagem(und) | N17: 700 | P17: Papel embalagem(und) | Q17: 24

Sheet Custeio e Precificação
C4: Preço Bolo de Cenoura com cobertura de Chocolate | G4: Preço Bolo de Cenoura com cobertura de Nutella | K4: Preço Piscininha de Chocolate | O4: Preço Piscininha de Nutella | S4: Preço Casadinho
C5: Ovos | E5: R$ 0,13 | G5: Ovos | I5: R$ 0,13 | K5: Ovos | M5: R$ 0,13 | O5: Ovos | Q5: R$ 0,13 | S5: Ovos | U5: R$ 0,26
C6: Óleo | E6: R$ 0,12 | G6: Óleo | I6: R$ 0,12 | K6: Óleo | M6: R$ 0,12 | O6: Óleo | Q6: R$ 0,12 | S6: Óleo | U6: R$ 0,24
C7: Açucar | E7: R$ 0,11 | G7: Açucar | I7: R$ 0,11 | K7: Açucar | M7: R$ 0,11 | O7: Açucar | Q7: R$ 0,11 | S7: Açucar | U7: R$ 0,22
C8: Farinha | E8: R$ 0,1 | G8: Farinha | I8: R$ 0,1 | K8: Farinha | M8: R$ 0,1 | O8: Farinha | Q8: R$ 0,1 | S8: Farinha | U8: R$ 0,2
C9: Cenoura | E9: R$ 0,14 | G9: Cenoura | I9: R$ 0,14 | K9: Cenoura | M9: R$ 0,14 | O9: Cenoura | Q9: R$ 0,14 | S9: Cenoura | U9: R$ 0,28
C10: Chocolate em pó | E10: R$ 0,12 | G10: Nutella | I10: R$ 1,64 | K10: Chocolate em pó | M10: R$ 0,12 | O10: Nutella | Q10: R$ 1,64 | S10: Nutella | U10: R$ 1,64
C11: Creme de Leite | E11: R$ 0,17 | G11: Embalagem | I11: 0.08 | K11: Creme de Leite | M11: R$ 0,17 | O11: Embalagem | Q11: 0.71 | S11: Chocolate em pó | U11: R$ 0,12
C12: Leite Condensado | E12: R$ 0,46 | G12: Custo Total | I12: R$ 2,32 | K12: Leite Condensado | M12: R$ 0,46 | O12: Custo Total | Q12: 2.95 | S12: Creme de Leite | U12: R$ 0,17
C13: Margarina | E13: R$ 0,02 | G13: Margem de Lucro | I13: 0.6907 | K13: Margarina | M13: R$ 0,02 | O13: Margem de Lucro | Q13: 0.6313 | S13: Leite Condensado | U13: R$ 0,46
C14: Embalagem | E14: 0.08 | G14: Preço Final | I14: R$ 7,50 | K14: Embalagem | M14: 0.71 | O14: Preço Final | Q14: 8 | S14: Margarina | U14: R$ 0,02
C15: Custo Total | E15: R$ 1,45 | K15: Custo Total | M15: 2.08 | S15: Embalagem | U15: 0.16
C16: Margem de Lucro | E16: 0.7769 | K16: Margem de Lucro | M16: 0.74 | S16: Custo Total | U16: 3.77
C17: Preço Final | E17: R$ 6,50 | K17: Preço Final | M17: 8 | S17: Margem de Lucro | U17: 0.6858
S18: Preço Final | U18: 12

Sheet Indicadores 
A7: MARKUP CASADINHA | E7: MARKUP CLÁSSICO | I7: MARKUP NUTELLA | M7: MARKUP PISCININHA DE NUTELLA | Q7: MARKUP PISCININHA DE BRIGADEIRO
A8: Custo Unitário | B8: Preço de Venda | C8: Markup | E8: Custo Unitário | F8: Preço de Venda | G8: Markup | I8: Custo Unitário | J8: Preço de Venda | K8: Markup | M8: Custo Unitário | N8: Preço de Venda | O8: Markup | Q8: Custo Unitário | R8: Preço de Venda | S8: Markup
A9: 3.77 | B9: 12 | C9: =B9/A9 -> 3.1830239 | E9: 1.45 | F9: 6.5 | G9: =F9/E9 -> 4.4827586 | I9: 2.32 | J9: 7.5 | K9: =J9/I9 -> 3.2327586 | M9: 2.95 | N9: 8 | O9: =N9/M9 -> 2.7118644 | Q9: 2.08 | R9: 8 | S9: =R9/Q9 -> 3.8461538
A12: MARGEM DE CONTRIBUIÇÂO CASADINHA | E12: MARGEM DE CONTRIBUIÇÂO CLÁSSICO | I12: MARGEM DE CONTRIBUIÇÂO NUTELLA | M12: MARGEM DE CONTRIBUIÇÂO PISCININHA DE NUTELLA | Q12: MARGEM DE CONTRIBUIÇÂO PISCININHA DE BRIGADEIRO
A13: Preço de Venda | B13: Custo | C13: MC | E13: Preço de Venda | F13: Custo | G13: MC | I13: Preço de Venda | J13: Custo | K13: MC | M13: Preço de Venda | N13: Custo | O13: MC | Q13: Preço de Venda | R13: Custo | S13: MC
A14: 12 | B14: 3.77 | C14: =A14-B14 -> 8.23 | E14: 6.5 | F14: 1.45 | G14: =E14-F14 -> 5.05 | I14: 7.5 | J14: 2.32 | K14: =I14-J14 -> 5.18 | M14: 8 | N14: 2.95 | O14: =M14-N14 -> 5.05 | Q14: 8 | R14: 2.08 | S14: =Q14-R14 -> 5.92
A17: LUCRATIVIDADE
A18: Produto | B18: Preço de Venda | C18: Custo | D18: Quantidade | E18: Lucro Unitário | F18: Lucro Total | G18: Lucratividade
A19: Casadinha | B19: 12 | C19: 3.77 | D19: 202 | E19: =B19-C19 -> 8.23 | F19: =D19*E19 -> 1662.46 | G19: =F19/(B19*D19) -> 0.68583333
A20: Clássico | B20: 6.5 | C20: 1.45 | D20: 460 | E20: =B20-C20 -> 5.05 | F20: =D20*E20 -> 2323 | G20: =F20/(B20*D20) -> 0.77692308
A21: Nutella | B21: 7.5 | C21: 2.32 | D21: 52 | E21: =B21-C21 -> 5.18 | F21: =D21*E21 -> 269.36 | G21: =F21/(B21*D21) -> 0.69066667
A22: Piscininhas | B22: 8 | C22: 2.95 | D22: 163 | E22: =B22-C22 -> 5.05 | F22: =D22*E22 -> 823.15 | G22: =F22/(B22*D22) -> 0.63125
A24: ROI
A25: 101.5176
